<?xml version="1.0" ?>
<!-- =================================================================================== -->
<!-- |    This document was autogenerated by xacro from ./urdf/mini_dog_model.xacro    | -->
<!-- |    EDITING THIS FILE BY HAND IS NOT RECOMMENDED                                 | -->
<!-- =================================================================================== -->
<robot name="Mini_Dog">
  <material name="blue">
    <color rgba="0 0 0.8 1"/>
  </material>
  <material name="white">
    <color rgba="1 1 1 1"/>
  </material>
  <link name="body">
    <visual>
      <origin rpy="0 0 0" xyz="0 0 0"/>
      <geometry>
        <mesh filename="../../meshes/collision/NOVA_SM3_low_res_body.stl"/>
      </geometry>
      <material name="blue"/>
    </visual>
    <collision>
      <geometry>
        <mesh filename="../../meshes/collision/NOVA_SM3_low_res_body.stl"/>
      </geometry>
    </collision>
    <inertial>
      <mass value="1"/>
      <origin rpy="0 0 0" xyz="-0.054576 1.067253 1.971264"/>
      <inertia ixx="649.842896" ixy="3.746272" ixz="-0.943389" iyy="87.661118" iyz="-45.790798" izz="638.730896"/>
    </inertial>
  </link>
  <joint name="body_to_front_left_coax" type="revolute">
    <parent link="body"/>
    <child link="front_left_coax"/>
    <origin xyz="1.40380628885496 -5.85830014656488 2.46921476091603"/>
    <axis xyz="0 1 0"/>
    <limit effort="100" lower="-1.2" upper="-0.3" velocity="100"/>
  </joint>
  <link name="front_left_coax">
    <visual>
      <origin rpy="0 0 0" xyz="0 0 0"/>
      <geometry>
        <mesh filename="../../meshes/collision/NOVA_SM3_low_res_left_coax.stl"/>
      </geometry>
      <material name="white"/>
    </visual>
    <collision>
      <geometry>
        <mesh filename="../../meshes/collision/NOVA_SM3_low_res_left_coax.stl"/>
      </geometry>
    </collision>
    <inertial>
      <mass value="0.1346"/>
      <origin rpy="0 0 0" xyz="0.193711 0.842311 -0.354898"/>
      <inertia ixx="1.184929" ixy="-0.016425" ixz="0.006891" iyy="1.036875" iyz="-0.016425" izz="0.835549"/>
    </inertial>
  </link>
  <joint name="front_left_coax_to_front_left_femur" type="continuous">
    <parent link="front_left_coax"/>
    <child link="front_left_femur"/>
    <origin xyz="1.03787235419847 0.879655749618321 -0.35136229251909"/>
    <axis xyz="1 0 0"/>
  </joint>
  <link name="front_left_femur">
    <visual>
      <origin rpy="0 0 0" xyz="0 0 0"/>
      <geometry>
        <mesh filename="../../meshes/collision/NOVA_SM3_low_res_left_femur.stl"/>
      </geometry>
      <material name="blue"/>
    </visual>
    <collision>
      <geometry>
        <mesh filename="../../meshes/collision/NOVA_SM3_low_res_left_femur.stl"/>
      </geometry>
    </collision>
    <inertial>
      <mass value="0.18113"/>
      <origin rpy="0 0 0" xyz="1.056116 1.262314 -1.127179"/>
      <inertia ixx="10.072502" ixy="-0.529121" ixz="0.516703" iyy="6.450747" iyz="4.604481" izz="7.59445"/>
    </inertial>
  </link>
  <joint name="front_left_femur_to_front_left_tibia" type="revolute">
    <parent link="front_left_femur"/>
    <child link="front_left_tibia"/>
    <origin xyz="0.39354148213741 2.65000312488549 -2.78071932641221"/>
    <axis xyz="1 0 0"/>
    <limit effort="100" lower="-1.25" upper="2.5" velocity="100"/>
  </joint>
  <link name="front_left_tibia">
    <visual>
      <origin rpy="0 0 0" xyz="0 0 0"/>
      <geometry>
        <mesh filename="../../meshes/collision/NOVA_SM3_low_res_left_tibia.stl"/>
      </geometry>
      <material name="white"/>
    </visual>
    <collision>
      <geometry>
        <mesh filename="../../meshes/collision/NOVA_SM3_low_res_left_tibia.stl"/>
      </geometry>
    </collision>
    <inertial>
      <mass value="0.14388"/>
      <origin rpy="0 0 0" xyz="0.825393 -0.56948 -1.21749"/>
      <inertia ixx="8.692493" ixy="-0.024831" ixz="0.021666" iyy="7.093554" iyz="-3.143373" izz="2.453905"/>
    </inertial>
  </link>
  <joint name="body_to_front_right_coax" type="revolute">
    <parent link="body"/>
    <child link="front_right_coax"/>
    <origin xyz="-1.40380628885496 -5.85830014656488 2.46921476091603"/>
    <axis xyz="0 -1 0"/>
    <limit effort="100" lower="-1.2" upper="-0.3" velocity="100"/>
  </joint>
  <link name="front_right_coax">
    <visual>
      <origin rpy="0 0 0" xyz="0 0 0"/>
      <geometry>
        <mesh filename="../../meshes/collision/NOVA_SM3_low_res_right_coax.stl"/>
      </geometry>
      <material name="white"/>
    </visual>
    <collision>
      <geometry>
        <mesh filename="../../meshes/collision/NOVA_SM3_low_res_right_coax.stl"/>
      </geometry>
    </collision>
    <inertial>
      <mass value="0.1346"/>
      <origin rpy="0 0 0" xyz="-0.193711 0.842311 -0.354898"/>
      <inertia ixx="1.184929" ixy="0.016425" ixz="-0.006891" iyy="1.036875" iyz="-0.016425" izz="0.835549"/>
    </inertial>
  </link>
  <joint name="front_right_coax_to_front_right_femur" type="continuous">
    <parent link="front_right_coax"/>
    <child link="front_right_femur"/>
    <origin xyz="-1.03787235419847 0.879655749618321 -0.35136229251909"/>
    <axis xyz="-1 0 0"/>
  </joint>
  <link name="front_right_femur">
    <visual>
      <origin rpy="0 0 0" xyz="0 0 0"/>
      <geometry>
        <mesh filename="../../meshes/collision/NOVA_SM3_low_res_right_femur.stl"/>
      </geometry>
      <material name="blue"/>
    </visual>
    <collision>
      <geometry>
        <mesh filename="../../meshes/collision/NOVA_SM3_low_res_right_femur.stl"/>
      </geometry>
    </collision>
    <inertial>
      <mass value="0.18113"/>
      <origin rpy="0 0 0" xyz="-1.056116 1.262314 -1.127179"/>
      <inertia ixx="10.072502" ixy="0.529121" ixz="-0.516703" iyy="6.450747" iyz="4.604481" izz="7.59445"/>
    </inertial>
  </link>
  <joint name="front_right_femur_to_front_right_tibia" type="revolute">
    <parent link="front_right_femur"/>
    <child link="front_right_tibia"/>
    <origin xyz="-0.39354148213741 2.65000312488549 -2.78071932641221"/>
    <axis xyz="-1 0 0"/>
    <limit effort="100" lower="-1.25" upper="2.5" velocity="100"/>
  </joint>
  <link name="front_right_tibia">
    <visual>
      <origin rpy="0 0 0" xyz="0 0 0"/>
      <geometry>
        <mesh filename="../../meshes/collision/NOVA_SM3_low_res_right_tibia.stl"/>
      </geometry>
      <material name="white"/>
    </visual>
    <collision>
      <geometry>
        <mesh filename="../../meshes/collision/NOVA_SM3_low_res_right_tibia.stl"/>
      </geometry>
    </collision>
    <inertial>
      <mass value="0.14388"/>
      <origin rpy="0 0 0" xyz="-0.825393 -0.56948 -1.21749"/>
      <inertia ixx="8.692493" ixy="0.024831" ixz="-0.021666" iyy="7.093554" iyz="-3.143373" izz="2.453905"/>
    </inertial>
  </link>
  <joint name="body_to_back_left_coax" type="revolute">
    <parent link="body"/>
    <child link="back_left_coax"/>
    <origin xyz="1.40380628885496 4.23649066259542 2.46921476091603"/>
    <axis xyz="0 1 0"/>
    <limit effort="100" lower="-1.2" upper="-0.3" velocity="100"/>
  </joint>
  <link name="back_left_coax">
    <visual>
      <origin rpy="0 0 0" xyz="0 0 0"/>
      <geometry>
        <mesh filename="../../meshes/collision/NOVA_SM3_low_res_left_coax.stl"/>
      </geometry>
      <material name="white"/>
    </visual>
    <collision>
      <geometry>
        <mesh filename="../../meshes/collision/NOVA_SM3_low_res_left_coax.stl"/>
      </geometry>
    </collision>
    <inertial>
      <mass value="0.1346"/>
      <origin rpy="0 0 0" xyz="0.193711 0.842311 -0.354898"/>
      <inertia ixx="1.184929" ixy="-0.016425" ixz="0.006891" iyy="1.036875" iyz="-0.016425" izz="0.835549"/>
    </inertial>
  </link>
  <joint name="back_left_coax_to_back_left_femur" type="continuous">
    <parent link="back_left_coax"/>
    <child link="back_left_femur"/>
    <origin xyz="1.03787235419847 0.879655749618321 -0.35136229251909"/>
    <axis xyz="1 0 0"/>
  </joint>
  <link name="back_left_femur">
    <visual>
      <origin rpy="0 0 0" xyz="0 0 0"/>
      <geometry>
        <mesh filename="../../meshes/collision/NOVA_SM3_low_res_left_femur.stl"/>
      </geometry>
      <material name="blue"/>
    </visual>
    <collision>
      <geometry>
        <mesh filename="../../meshes/collision/NOVA_SM3_low_res_left_femur.stl"/>
      </geometry>
    </collision>
    <inertial>
      <mass value="0.18113"/>
      <origin rpy="0 0 0" xyz="1.056116 1.262314 -1.127179"/>
      <inertia ixx="10.072502" ixy="-0.529121" ixz="0.516703" iyy="6.450747" iyz="4.604481" izz="7.59445"/>
    </inertial>
  </link>
  <joint name="back_left_femur_to_back_left_tibia" type="revolute">
    <parent link="back_left_femur"/>
    <child link="back_left_tibia"/>
    <origin xyz="0.39354148213741 2.65000312488549 -2.78071932641221"/>
    <axis xyz="1 0 0"/>
    <limit effort="100" lower="-1.25" upper="2.5" velocity="100"/>
  </joint>
  <link name="back_left_tibia">
    <visual>
      <origin rpy="0 0 0" xyz="0 0 0"/>
      <geometry>
        <mesh filename="../../meshes/collision/NOVA_SM3_low_res_left_tibia.stl"/>
      </geometry>
      <material name="white"/>
    </visual>
    <collision>
      <geometry>
        <mesh filename="../../meshes/collision/NOVA_SM3_low_res_left_tibia.stl"/>
      </geometry>
    </collision>
    <inertial>
      <mass value="0.14388"/>
      <origin rpy="0 0 0" xyz="0.825393 -0.56948 -1.21749"/>
      <inertia ixx="8.692493" ixy="-0.024831" ixz="0.021666" iyy="7.093554" iyz="-3.143373" izz="2.453905"/>
    </inertial>
  </link>
  <joint name="body_to_back_right_coax" type="revolute">
    <parent link="body"/>
    <child link="back_right_coax"/>
    <origin xyz="-1.40380628885496 4.23649066259542 2.46921476091603"/>
    <axis xyz="0 -1 0"/>
    <limit effort="100" lower="-1.2" upper="-0.3" velocity="100"/>
  </joint>
  <link name="back_right_coax">
    <visual>
      <origin rpy="0 0 0" xyz="0 0 0"/>
      <geometry>
        <mesh filename="../../meshes/collision/NOVA_SM3_low_res_right_coax.stl"/>
      </geometry>
      <material name="white"/>
    </visual>
    <collision>
      <geometry>
        <mesh filename="../../meshes/collision/NOVA_SM3_low_res_right_coax.stl"/>
      </geometry>
    </collision>
    <inertial>
      <mass value="0.1346"/>
      <origin rpy="0 0 0" xyz="-0.193711 0.842311 -0.354898"/>
      <inertia ixx="1.184929" ixy="0.016425" ixz="-0.006891" iyy="1.036875" iyz="-0.016425" izz="0.835549"/>
    </inertial>
  </link>
  <joint name="back_right_coax_to_back_right_femur" type="continuous">
    <parent link="back_right_coax"/>
    <child link="back_right_femur"/>
    <origin xyz="-1.03787235419847 0.879655749618321 -0.35136229251909"/>
    <axis xyz="-1 0 0"/>
  </joint>
  <link name="back_right_femur">
    <visual>
      <origin rpy="0 0 0" xyz="0 0 0"/>
      <geometry>
        <mesh filename="../../meshes/collision/NOVA_SM3_low_res_right_femur.stl"/>
      </geometry>
      <material name="blue"/>
    </visual>
    <collision>
      <geometry>
        <mesh filename="../../meshes/collision/NOVA_SM3_low_res_right_femur.stl"/>
      </geometry>
    </collision>
    <inertial>
      <mass value="0.18113"/>
      <origin rpy="0 0 0" xyz="-1.056116 1.262314 -1.127179"/>
      <inertia ixx="10.072502" ixy="0.529121" ixz="-0.516703" iyy="6.450747" iyz="4.604481" izz="7.59445"/>
    </inertial>
  </link>
  <joint name="back_right_femur_to_back_right_tibia" type="revolute">
    <parent link="back_right_femur"/>
    <child link="back_right_tibia"/>
    <origin xyz="-0.39354148213741 2.65000312488549 -2.78071932641221"/>
    <axis xyz="-1 0 0"/>
    <limit effort="100" lower="-1.25" upper="2.5" velocity="100"/>
  </joint>
  <link name="back_right_tibia">
    <visual>
      <origin rpy="0 0 0" xyz="0 0 0"/>
      <geometry>
        <mesh filename="../../meshes/collision/NOVA_SM3_low_res_right_tibia.stl"/>
      </geometry>
      <material name="white"/>
    </visual>
    <collision>
      <geometry>
        <mesh filename="../../meshes/collision/NOVA_SM3_low_res_right_tibia.stl"/>
      </geometry>
    </collision>
    <inertial>
      <mass value="0.14388"/>
      <origin rpy="0 0 0" xyz="-0.825393 -0.56948 -1.21749"/>
      <inertia ixx="8.692493" ixy="0.024831" ixz="-0.021666" iyy="7.093554" iyz="-3.143373" izz="2.453905"/>
    </inertial>
  </link>
</robot>
